<mujoco model="g1_29dof_with_hand_rev_1_0">
  <compiler angle="radian" meshdir="assets"/>

  <option integrator="implicitfast"/>

  <default>
    <default class="g1">
      <site rgba="1 0 0 1" size="0.01" group="5"/>
      <joint armature="0.01" frictionloss="0.3"/>
      <position kp="500" dampratio="1" inheritrange="1"/>
      <default class="visual">
        <geom group="2" type="mesh" contype="0" conaffinity="0" density="0" material="metal"/>
      </default>
      <default class="collision">
        <geom group="3" type="mesh"/>
        <default class="foot">
          <geom type="sphere" size="0.005" priority="1" friction="0.6" condim="3"/>
        </default>
      </default>
    </default>
    <default class="inspire">
       <joint damping="3"/>
        <muscle ctrllimited="true" ctrlrange="0 100"/>
        <motor ctrllimited="true" ctrlrange="-3 3" gear="1"/>
        <position ctrllimited="true" kp="10"/>
        <geom rgba="1 1 1 1"/>
    </default>
  </default>

  <asset>
    <material name="black" rgba="0.2 0.2 0.2 1"/>
    <material name="metal" rgba="0.7 0.7 0.7 1"/>

    <mesh file="pelvis.STL"/>
    <mesh file="pelvis_contour_link.STL"/>
    <mesh file="left_hip_pitch_link.STL"/>
    <mesh file="left_hip_roll_link.STL"/>
    <mesh file="left_hip_yaw_link.STL"/>
    <mesh file="left_knee_link.STL"/>
    <mesh file="left_ankle_pitch_link.STL"/>
    <mesh file="left_ankle_roll_link.STL"/>
    <mesh file="right_hip_pitch_link.STL"/>
    <mesh file="right_hip_roll_link.STL"/>
    <mesh file="right_hip_yaw_link.STL"/>
    <mesh file="right_knee_link.STL"/>
    <mesh file="right_ankle_pitch_link.STL"/>
    <mesh file="right_ankle_roll_link.STL"/>
    <mesh name="waist_yaw_link" file="waist_yaw_link_rev_1_0.STL"/>
    <mesh name="waist_roll_link" file="waist_roll_link_rev_1_0.STL"/>
    <mesh name="torso_link" file="torso_link_rev_1_0.STL"/>
    <mesh file="logo_link.STL"/>
    <mesh file="head_link.STL"/>
    <mesh file="left_shoulder_pitch_link.STL"/>
    <mesh file="left_shoulder_roll_link.STL"/>
    <mesh file="left_shoulder_yaw_link.STL"/>
    <mesh file="left_elbow_link.STL"/>
    <mesh file="left_wrist_roll_link.STL"/>
    <mesh name="left_wrist_pitch_link" file="left_wrist_pitch_link.STL"/>
    <mesh file="left_wrist_yaw_link.STL"/>
    <mesh file="left_hand_palm_link.STL"/>
    <mesh file="left_hand_thumb_0_link.STL"/>
    <mesh file="left_hand_thumb_1_link.STL"/>
    <mesh file="left_hand_thumb_2_link.STL"/>
    <mesh file="left_hand_middle_0_link.STL"/>
    <mesh file="left_hand_middle_1_link.STL"/>
    <mesh file="left_hand_index_0_link.STL"/>
    <mesh file="left_hand_index_1_link.STL"/>
    <mesh file="right_shoulder_pitch_link.STL"/>
    <mesh file="right_shoulder_roll_link.STL"/>
    <mesh file="right_shoulder_yaw_link.STL"/>
    <mesh file="right_elbow_link.STL"/>
    <mesh file="right_wrist_roll_link.STL"/>
    <mesh file="right_wrist_pitch_link.STL"/>
    <mesh file="right_wrist_yaw_link.STL"/>
    <mesh file="right_hand_palm_link.STL"/>
    <mesh file="right_hand_thumb_0_link.STL"/>
    <mesh file="right_hand_thumb_1_link.STL"/>
    <mesh file="right_hand_thumb_2_link.STL"/>
    <mesh file="right_hand_middle_0_link.STL"/>
    <mesh file="right_hand_middle_1_link.STL"/>
    <mesh file="right_hand_index_0_link.STL"/>
    <mesh file="right_hand_index_1_link.STL"/>

     <mesh name="r_palm_vis" file="meshes/inspire_hands/rh_base_link.STL"/>
        <mesh name="r_palm_col" file="meshes/inspire_hands/rh_base_link.STL"/>

        <mesh name="r_thumb_proximal_1_vis" file="meshes/inspire_hands/rh_Link11.STL"/>
        <mesh name="r_thumb_proximal_1_col" file="meshes/inspire_hands/rh_Link11.STL"/>

        <mesh name="r_thumb_proximal_2_vis" file="meshes/inspire_hands/rh_Link12.STL"/>
        <mesh name="r_thumb_proximal_2_col" file="meshes/inspire_hands/rh_Link12.STL"/>

        <mesh name="r_thumb_middle_vis" file="meshes/inspire_hands/rh_Link13.STL"/>
        <mesh name="r_thumb_middle_col" file="meshes/inspire_hands/rh_Link13.STL"/>


        <mesh name="r_thumb_distal_vis" file="meshes/inspire_hands/rh_Link14.STL"/>
        <mesh name="r_thumb_distal_col" file="meshes/inspire_hands/rh_Link14.STL"/>

        <mesh name="r_index_proximal_vis" file="meshes/inspire_hands/rh_Link15.STL"/>
        <mesh name="r_index_proximal_col" file="meshes/inspire_hands/rh_Link15.STL"/>

        <mesh name="r_index_distal_vis" file="meshes/inspire_hands/rh_Link16.STL"/>
        <mesh name="r_index_distal_col" file="meshes/inspire_hands/rh_Link16.STL"/>

        <mesh name="r_middle_proximal_vis" file="meshes/inspire_hands/rh_Link17.STL"/>
        <mesh name="r_middle_proximal_col" file="meshes/inspire_hands/rh_Link17.STL"/>

        <mesh name="r_middle_distal_vis" file="meshes/inspire_hands/rh_Link18.STL"/>
        <mesh name="r_middle_distal_col" file="meshes/inspire_hands/rh_Link18.STL"/>


        <mesh name="r_ring_proximal_vis" file="meshes/inspire_hands/rh_Link19.STL"/>
        <mesh name="r_ring_proximal_col" file="meshes/inspire_hands/rh_Link19.STL"/>

        <mesh name="r_ring_distal_vis" file="meshes/inspire_hands/rh_Link20.STL"/>
        <mesh name="r_ring_distal_col" file="meshes/inspire_hands/rh_Link20.STL"/>


        <mesh name="r_pinky_proximal_vis" file="meshes/inspire_hands/rh_Link21.STL"/>
        <mesh name="r_pinky_proximal_col" file="meshes/inspire_hands/rh_Link21.STL"/>

        <mesh name="r_pinky_distal_vis" file="meshes/inspire_hands/rh_Link22.STL"/>
        <mesh name="r_pinky_distal_col" file="meshes/inspire_hands/rh_Link22.STL"/>

        <material name="site_right_hand" rgba="0.1882 0.1882 0.1882 0"/>

        <material name="r_base_material" rgba="0 0 0 1"/>
        <material name="r_thumb_material" rgba="0 0 0 1"/>
        <material name="r_index_material" rgba="0 0 0 1"/>
        <material name="r_middle_material" rgba="0 0 0 1"/>
        <material name="r_ring_material" rgba="0 0 0 1"/>
        <material name="r_pinky_material" rgba="0 0 0 1"/>

        <material name="r_thumb_distal_material" rgba="0 0 0 1"/>

        

      <mesh name="l_palm_vis" file="meshes/inspire_hands/lh_base_link.STL"/>
        <mesh name="l_palm_col" file="meshes/inspire_hands/lh_base_link.STL"/>

        <mesh name="l_thumb_proximal_1_vis" file="meshes/inspire_hands/lh_Link11.STL"/>
        <mesh name="l_thumb_proximal_1_col" file="meshes/inspire_hands/lh_Link11.STL"/>

        <mesh name="l_thumb_proximal_2_vis" file="meshes/inspire_hands/lh_Link12.STL"/>
        <mesh name="l_thumb_proximal_2_col" file="meshes/inspire_hands/lh_Link12.STL"/>

        <mesh name="l_thumb_middle_vis" file="meshes/inspire_hands/lh_Link13.STL"/>
        <mesh name="l_thumb_middle_col" file="meshes/inspire_hands/lh_Link13.STL"/>


        <mesh name="l_thumb_distal_vis" file="meshes/inspire_hands/lh_Link14.STL"/>
        <mesh name="l_thumb_distal_col" file="meshes/inspire_hands/lh_Link14.STL"/>

        <mesh name="l_index_proximal_vis" file="meshes/inspire_hands/lh_Link15.STL"/>
        <mesh name="l_index_proximal_col" file="meshes/inspire_hands/lh_Link15.STL"/>

        <mesh name="l_index_distal_vis" file="meshes/inspire_hands/lh_Link16.STL"/>
        <mesh name="l_index_distal_col" file="meshes/inspire_hands/lh_Link16.STL"/>

        <mesh name="l_middle_proximal_vis" file="meshes/inspire_hands/lh_Link17.STL"/>
        <mesh name="l_middle_proximal_col" file="meshes/inspire_hands/lh_Link17.STL"/>

        <mesh name="l_middle_distal_vis" file="meshes/inspire_hands/lh_Link18.STL"/>
        <mesh name="l_middle_distal_col" file="meshes/inspire_hands/lh_Link18.STL"/>


        <mesh name="l_ring_proximal_vis" file="meshes/inspire_hands/lh_Link19.STL"/>
        <mesh name="l_ring_proximal_col" file="meshes/inspire_hands/lh_Link19.STL"/>

        <mesh name="l_ring_distal_vis" file="meshes/inspire_hands/lh_Link20.STL"/>
        <mesh name="l_ring_distal_col" file="meshes/inspire_hands/lh_Link20.STL"/>


        <mesh name="l_pinky_proximal_vis" file="meshes/inspire_hands/lh_Link21.STL"/>
        <mesh name="l_pinky_proximal_col" file="meshes/inspire_hands/lh_Link21.STL"/>

        <mesh name="l_pinky_distal_vis" file="meshes/inspire_hands/lh_Link22.STL"/>
        <mesh name="l_pinky_distal_col" file="meshes/inspire_hands/lh_Link22.STL"/>
        <material name="site_left_hand" rgba="0.1882 0.1882 0.1882 0"/>

        <material name="l_base_material" rgba="0 0 0 1"/>
        <material name="l_thumb_material" rgba="0 0 0 1"/>
        <material name="l_index_material" rgba="0 0 0 1"/>
        <material name="l_middle_material" rgba="0 0 0 1"/>
        <material name="l_ring_material" rgba="0 0 0 1"/>
        <material name="l_pinky_material" rgba="0 0 0 1"/>

        <material name="l_thumb_distal_material" rgba="0 0 0 1"/>

  </asset>

  <worldbody>
    <light pos="1 0 3.5" dir="0 0 -1" directional="true"/>
    <body name="pelvis" pos="0 0 0.793" childclass="g1">
      <inertial pos="0 0 -0.07605" quat="1 0 -0.000399148 0" mass="3.813" diaginertia="0.010549 0.0093089 0.0079184"/>
      <freejoint name="floating_base_joint"/>
      <geom class="visual" material="black" mesh="pelvis"/>
      <geom class="visual" mesh="pelvis_contour_link"/>
      <geom class="collision" mesh="pelvis_contour_link"/>
      <site name="head" pos="0 0 0.5"/>
      <site name="imu_in_pelvis" size="0.01" pos="0.04525 0 -0.08339"/>
      <body name="left_hip_pitch_link" pos="0 0.064452 -0.1027">
        <inertial pos="0.002741 0.047791 -0.02606" quat="0.954862 0.293964 0.0302556 0.030122" mass="1.35"
          diaginertia="0.00181517 0.00153422 0.00116212"/>
        <joint name="left_hip_pitch_joint" axis="0 1 0" range="-2.5307 2.8798" actuatorfrcrange="-88 88"/>
        <geom class="visual" material="black" mesh="left_hip_pitch_link"/>
        <geom class="collision" mesh="left_hip_pitch_link"/>
        <body name="left_hip_roll_link" pos="0 0.052 -0.030465" quat="0.996179 0 -0.0873386 0">
          <inertial pos="0.029812 -0.001045 -0.087934" quat="0.977808 -1.97119e-05 0.205576 -0.0403793" mass="1.52"
            diaginertia="0.00254986 0.00241169 0.00148755"/>
          <joint name="left_hip_roll_joint" axis="1 0 0" range="-0.5236 2.9671" actuatorfrcrange="-139 139"/>
          <geom class="visual" mesh="left_hip_roll_link"/>
          <!-- <geom class="collision" mesh="left_hip_roll_link"/> -->
          <geom name="left_thigh" class="collision" type="capsule" size="0.07" fromto="0.02 0 0 0.02 0 -0.2" group="3" rgba=".2 .6 .2 .3"/>
          <body name="left_hip_yaw_link" pos="0.025001 0 -0.12412">
            <inertial pos="-0.057709 -0.010981 -0.15078" quat="0.600598 0.15832 0.223482 0.751181" mass="1.702"
              diaginertia="0.00776166 0.00717575 0.00160139"/>
            <joint name="left_hip_yaw_joint" axis="0 0 1" range="-2.7576 2.7576" actuatorfrcrange="-88 88"/>
            <geom class="visual" mesh="left_hip_yaw_link"/>
            <geom class="collision" mesh="left_hip_yaw_link"/>
            <body name="left_knee_link" pos="-0.078273 0.0021489 -0.17734" quat="0.996179 0 0.0873386 0">
              <inertial pos="0.005457 0.003964 -0.12074" quat="0.923418 -0.0327699 0.0158246 0.382067" mass="1.932"
                diaginertia="0.0113804 0.0112778 0.00146458"/>
              <joint name="left_knee_joint" axis="0 1 0" range="-0.087267 2.8798" actuatorfrcrange="-139 139"/>
              <geom class="visual" mesh="left_knee_link"/>
              <geom class="collision" mesh="left_knee_link"/>
              <body name="left_ankle_pitch_link" pos="0 -9.4445e-05 -0.30001">
                <inertial pos="-0.007269 0 0.011137" quat="0.603053 0.369225 0.369225 0.603053" mass="0.074"
                  diaginertia="1.89e-05 1.40805e-05 6.9195e-06"/>
                <joint name="left_ankle_pitch_joint" axis="0 1 0" range="-0.87267 0.5236" actuatorfrcrange="-50 50"/>
                <geom class="visual" mesh="left_ankle_pitch_link"/>
                <geom class="collision" mesh="left_ankle_pitch_link"/>
                <body name="left_ankle_roll_link" pos="0 0 -0.017558">
                  <inertial pos="0.026505 0 -0.016425" quat="-0.000481092 0.728482 -0.000618967 0.685065" mass="0.608"
                    diaginertia="0.00167218 0.0016161 0.000217621"/>
                  <joint name="left_ankle_roll_joint" axis="1 0 0" range="-0.2618 0.2618" actuatorfrcrange="-50 50"/>
                  <geom class="visual" material="black" mesh="left_ankle_roll_link"/>
                  <geom class="foot" pos="-0.05 0.025 -0.03"/>
                  <geom class="foot" pos="-0.05 -0.025 -0.03"/>
                  <geom class="foot" pos="0.12 0.03 -0.03"/>
                  <geom class="foot" pos="0.12 -0.03 -0.03"/>
                  <site name="left_foot"/>
                </body>
              </body>
            </body>
          </body>
        </body>
      </body>
      <body name="right_hip_pitch_link" pos="0 -0.064452 -0.1027">
        <inertial pos="0.002741 -0.047791 -0.02606" quat="0.954862 -0.293964 0.0302556 -0.030122" mass="1.35"
          diaginertia="0.00181517 0.00153422 0.00116212"/>
        <joint name="right_hip_pitch_joint" axis="0 1 0" range="-2.5307 2.8798" actuatorfrcrange="-88 88"/>
        <geom class="visual" material="black" mesh="right_hip_pitch_link"/>
        <geom class="collision" mesh="right_hip_pitch_link"/>
        <body name="right_hip_roll_link" pos="0 -0.052 -0.030465" quat="0.996179 0 -0.0873386 0">
          <inertial pos="0.029812 0.001045 -0.087934" quat="0.977808 1.97119e-05 0.205576 0.0403793" mass="1.52"
            diaginertia="0.00254986 0.00241169 0.00148755"/>
          <joint name="right_hip_roll_joint" axis="1 0 0" range="-2.9671 0.5236" actuatorfrcrange="-139 139"/>
          <geom class="visual" mesh="right_hip_roll_link"/>
          <!-- <geom class="collision" mesh="right_hip_roll_link"/> -->
          <geom name="right_thigh" class="collision" type="capsule" size="0.07" fromto="0.02 0 0 0.02 0 -0.2" group="3" rgba=".2 .6 .2 .3"/>
          <body name="right_hip_yaw_link" pos="0.025001 0 -0.12412">
            <inertial pos="-0.057709 0.010981 -0.15078" quat="0.751181 0.223482 0.15832 0.600598" mass="1.702"
              diaginertia="0.00776166 0.00717575 0.00160139"/>
            <joint name="right_hip_yaw_joint" axis="0 0 1" range="-2.7576 2.7576" actuatorfrcrange="-88 88"/>
            <geom class="visual" mesh="right_hip_yaw_link"/>
            <geom class="collision" mesh="right_hip_yaw_link"/>
            <body name="right_knee_link" pos="-0.078273 -0.0021489 -0.17734" quat="0.996179 0 0.0873386 0">
              <inertial pos="0.005457 -0.003964 -0.12074" quat="0.923439 0.0345276 0.0116333 -0.382012" mass="1.932"
                diaginertia="0.011374 0.0112843 0.00146452"/>
              <joint name="right_knee_joint" axis="0 1 0" range="-0.087267 2.8798" actuatorfrcrange="-139 139"/>
              <geom class="visual" mesh="right_knee_link"/>
              <geom class="collision" mesh="right_knee_link"/>
              <body name="right_ankle_pitch_link" pos="0 9.4445e-05 -0.30001">
                <inertial pos="-0.007269 0 0.011137" quat="0.603053 0.369225 0.369225 0.603053" mass="0.074"
                  diaginertia="1.89e-05 1.40805e-05 6.9195e-06"/>
                <joint name="right_ankle_pitch_joint" axis="0 1 0" range="-0.87267 0.5236" actuatorfrcrange="-50 50"/>
                <geom class="visual" mesh="right_ankle_pitch_link"/>
                <geom class="collision" mesh="right_ankle_pitch_link"/>
                <body name="right_ankle_roll_link" pos="0 0 -0.017558">
                  <inertial pos="0.026505 0 -0.016425" quat="0.000481092 0.728482 0.000618967 0.685065" mass="0.608"
                    diaginertia="0.00167218 0.0016161 0.000217621"/>
                  <joint name="right_ankle_roll_joint" axis="1 0 0" range="-0.2618 0.2618" actuatorfrcrange="-50 50"/>
                  <geom class="visual" material="black" mesh="right_ankle_roll_link"/>
                  <geom class="foot" pos="-0.05 0.025 -0.03"/>
                  <geom class="foot" pos="-0.05 -0.025 -0.03"/>
                  <geom class="foot" pos="0.12 0.03 -0.03"/>
                  <geom class="foot" pos="0.12 -0.03 -0.03"/>
                  <site name="right_foot"/>
                </body>
              </body>
            </body>
          </body>
        </body>
      </body>
      <body name="waist_yaw_link">
        <inertial pos="0.003494 0.000233 0.018034" quat="0.289697 0.591001 -0.337795 0.672821" mass="0.214"
          diaginertia="0.000163531 0.000107714 0.000102205"/>
        <joint name="waist_yaw_joint" axis="0 0 1" range="-2.618 2.618" actuatorfrcrange="-88 88"/>
        <geom class="visual" mesh="waist_yaw_link"/>
        <body name="waist_roll_link" pos="-0.0039635 0 0.044">
          <inertial pos="0 2.3e-05 0" quat="0.5 0.5 -0.5 0.5" mass="0.086" diaginertia="8.245e-06 7.079e-06 6.339e-06"/>
          <joint name="waist_roll_joint" axis="1 0 0" range="-0.52 0.52" actuatorfrcrange="-50 50"/>
          <geom class="visual" mesh="waist_roll_link"/>
          <body name="torso_link">
            <inertial pos="0.00203158 0.000339683 0.184568" quat="0.999803 -6.03319e-05 0.0198256 0.00131986"
              mass="7.818" diaginertia="0.121847 0.109825 0.0273735"/>
            <joint name="waist_pitch_joint" axis="0 1 0" range="-0.52 0.52" actuatorfrcrange="-50 50"/>
            <geom class="visual" mesh="torso_link"/>
            <geom class="collision" mesh="torso_link"/>
            <geom pos="0.0039635 0 -0.044" quat="1 0 0 0" class="visual" material="black" mesh="logo_link"/>
            <geom pos="0.0039635 0 -0.044" class="visual" material="black" mesh="head_link"/>
            <geom pos="0.0039635 0 -0.044" class="collision" mesh="head_link"/>
            <site name="imu_in_torso" size="0.01" pos="-0.03959 -0.00224 0.14792"/>
            <body name="left_shoulder_pitch_link" pos="0.0039563 0.10022 0.24778"
              quat="0.990264 0.139201 1.38722e-05 -9.86868e-05">
              <inertial pos="0 0.035892 -0.011628" quat="0.654152 0.0130458 -0.326267 0.68225" mass="0.718"
                diaginertia="0.000465864 0.000432842 0.000406394"/>
              <joint name="left_shoulder_pitch_joint" axis="0 1 0" range="-3.0892 2.6704" actuatorfrcrange="-25 25"/>
              <geom class="visual" mesh="left_shoulder_pitch_link"/>
              <geom size="0.03 0.025" pos="0 0.04 -0.01" quat="0.707107 0 0.707107 0" type="cylinder" class="collision"/>
              <body name="left_shoulder_roll_link" pos="0 0.038 -0.013831" quat="0.990268 -0.139172 0 0">
                <inertial pos="-0.000227 0.00727 -0.063243" quat="0.701256 -0.0196223 -0.00710317 0.712604" mass="0.643"
                  diaginertia="0.000691311 0.000618011 0.000388977"/>
                <joint name="left_shoulder_roll_joint" axis="1 0 0" range="-1.5882 2.2515" actuatorfrcrange="-25 25"/>
                <geom class="visual" mesh="left_shoulder_roll_link"/>
                <geom size="0.03 0.015" pos="-0.004 0.006 -0.053" type="cylinder" class="collision"/>
                <body name="left_shoulder_yaw_link" pos="0 0.00624 -0.1032">
                  <inertial pos="0.010773 -0.002949 -0.072009" quat="0.716879 -0.0964829 -0.0679942 0.687134"
                    mass="0.734" diaginertia="0.00106187 0.00103217 0.000400661"/>
                  <joint name="left_shoulder_yaw_joint" axis="0 0 1" range="-2.618 2.618" actuatorfrcrange="-25 25"/>
                  <geom class="visual" mesh="left_shoulder_yaw_link"/>
                  <geom class="collision" mesh="left_shoulder_yaw_link"/>
                  <body name="left_elbow_link" pos="0.015783 0 -0.080518">
                    <inertial pos="0.064956 0.004454 -0.010062" quat="0.541765 0.636132 0.388821 0.388129" mass="0.6"
                      diaginertia="0.000443035 0.000421612 0.000259353"/>
                    <joint name="left_elbow_joint" axis="0 1 0" range="-1.0472 2.0944" actuatorfrcrange="-25 25"/>
                    <geom class="visual" mesh="left_elbow_link"/>
                    <geom name="left_elbow_collision" class="collision" type="capsule" size="0.05" fromto="0 0 0 0.1 0 0" rgba=".2 .6 .2 .2" group="3"/>
                    <body name="left_wrist_roll_link" pos="0.1 0.00188791 -0.01">
                      <inertial pos="0.0171394 0.000537591 4.8864e-07" quat="0.575338 0.411667 -0.574906 0.411094"
                        mass="0.085445" diaginertia="5.48211e-05 4.96646e-05 3.57798e-05"/>
                      <joint name="left_wrist_roll_joint" axis="1 0 0" range="-1.97222 1.97222"
                        actuatorfrcrange="-25 25"/>
                      <geom class="visual" mesh="left_wrist_roll_link"/>
                      <geom class="collision" mesh="left_wrist_roll_link"/>
                      <body name="left_wrist_pitch_link" pos="0.038 0 0">
                        <inertial pos="0.0229999 -0.00111685 -0.00111658" quat="0.249998 0.661363 0.293036 0.643608"
                          mass="0.48405" diaginertia="0.000430353 0.000429873 0.000164648"/>
                        <joint name="left_wrist_pitch_joint" axis="0 1 0" range="-1.61443 1.61443"
                          actuatorfrcrange="-5 5"/>
                        <geom class="visual" mesh="left_wrist_pitch_link"/>
                        <geom class="collision" mesh="left_wrist_pitch_link"/>
                        <body name="left_wrist_yaw_link" pos="0.046 0 0">
                          <inertial pos="0.0885506 0.00212216 -0.000374562" quat="0.487149 0.493844 0.513241 0.505358"
                            mass="0.457415" diaginertia="0.00105989 0.000895419 0.000323842"/>
                          <joint name="left_wrist_yaw_joint" axis="0 0 1" range="-1.61443 1.61443"
                            actuatorfrcrange="-5 5"/>

                            <geom class="visual" mesh="left_wrist_yaw_link"/>
                          <geom class="collision" mesh="left_wrist_yaw_link"/>

                                  <site name="left_palm" pos="0.1 0 0"/>

                              <body name="left_hand" pos="0.03 0 0" euler="0 0 0" childclass="inspire">

                              <body name="left_hand_fake" pos="0 0 0"  euler="3.14 -3.14 -1.67">

                                  <!-- <geom name="x_axis" type="cylinder" pos="0 0 0" size="0.005 0.1" rgba="1 0 0 1" euler="0 0 0" group="1" contype="0" conaffinity="0"/>
                                  <geom name="y_axis" type="cylinder" pos="0 0 0" size="0.005 0.1" rgba="0 1 0 1" euler="0 1.5708 0" group="1" contype="0" conaffinity="0"/>
                                  <geom name="z_axis" type="cylinder" pos="0 0 0" size="0.005 0.1" rgba="0 0 1 1" euler="1.5708 0 0" group="1" contype="0" conaffinity="0"/> -->

                                  <site name="l_ft_frame" pos="0 0 0" size="0.01 0.01 0.01" rgba="1 0 0 0" type="sphere" group="1"/>
                                  <inertial diaginertia="0 0 0" mass="0" pos="0 0 0"/>
                                  <body name="l_eef" pos="0 0 0" quat="0.707 0. -0.707 0.">
                                      <site name="l_grip_site" pos="0 0 0" size="0.01 0.01 0.01" rgba="1 1 0 1" type="sphere" group="2"/>
                                      <site name="l_ee_x" pos="0.1 0 0" size="0.005 .1"  quat="0.707105  0 0.707108 0 " rgba="1 0 0 0" type="cylinder" group="1"/>
                                      <site name="l_ee_y" pos="0 0.1 0" size="0.005 .1" quat="0.707105 0.707108 0 0" rgba="0 1 0 0" type="cylinder" group="1"/>
                                      <site name="l_ee_z" pos="0 0 0.1" size="0.005 .1" quat="1 0 0 0" rgba="0 0 1 0" type="cylinder" group="1"/>
                                      <!-- This site was added for visualization. -->
                                      <!-- <site name="l_grip_site_cylinder" pos="0 0 0" quat="-0.5 -0.5 -0.5 0.5" size="0.005 0.5" rgba="0 1 0 0.3" type="cylinder" group="1"/> -->
                                  </body>


                                  <!-- Palm  -->
                                  <body name="l_palm" pos="0 0 0">
                                      <!-- <inertial pos="-0.0014004 -0.052388 -0.0022404" quat="1 0 0 0" mass="0.10331">
                                          <inertia ixx="9.814E-05" ixy="3.1871E-06" ixz="-1.475E-06" iyy="6.4612E-05" iyz="2.4108E-06" izz="5.5131E-05"/>
                                      </inertial> -->
                                      <!-- Palm Visual -->
                                      <geom name="l_palm_vis" type="mesh" mesh="l_palm_vis" material="l_base_material" group="1" contype="0" conaffinity="0"/>
                                      <!-- Palm Collision -->
                                      <geom name="l_palm_col" type="mesh" mesh="l_palm_col" mass="0.1" />

                                      <!-- Thumb -->
                                      <body name="l_thumb" pos="0. 0. 0.">
                                          <!-- Thumb Proximal 1 -->
                                          <body name="l_thumb_proximal_1" pos="-0.01496 -0.0375 0.02045" quat="0.5 0.5 -0.5 0.5">
                                              <joint name="joint_l_thumb_proximal_1" type="hinge" pos="0 0 0" axis="0 0 1" range="0 1.30" limited="true" damping="3"/>
                                              <!-- <site name="site_thumb_proximal_1" size="0.01" material="site_left_hand"/> -->
                                              <geom name="l_thumb_proximal_vis" type="mesh" mesh="l_thumb_proximal_1_vis" material="l_thumb_material" group="1" contype="0" conaffinity="0"> </geom>
                                              <geom name="l_thumb_proximal_col" type="mesh" mesh="l_thumb_proximal_1_col" mass="0.1" />

                                              <!-- Thumb Proximal 2 -->
                                              <body name="l_thumb_proximal_2" pos="0.0099867 0.0098242 -0.0089" quat="0.705 -0.705 -0.060 0.060">
                                                  <joint name="joint_l_thumb_proximal_2" type="hinge" pos="0 0 0" axis="0 0 -1" range="0 0.68" limited="true" damping="3"/>
                                                  <geom name="l_thumb_proximal_2_vis" type="mesh" mesh="l_thumb_proximal_2_vis" material="l_thumb_material" group="1" contype="0" conaffinity="0"> </geom>
                                                  <geom name="l_thumb_proximal_2_col" type="mesh" mesh="l_thumb_proximal_2_col" mass="0.1" />

                                                  <site name="site_l_thumb_proximal_2" size="0.01" material="site_left_hand"/>

                                                  <!-- Thumb Middle -->
                                                  <body name="l_thumb_middle" pos="0.04407 -0.034553 -0.0008" quat="1 0 0 0">
                                                      <joint name="joint_l_thumb_middle" type="hinge" pos="0 0 0" axis="0 0 -1" range="0 0.68" limited="true" damping="3"/>
                                                      <geom name="l_thumb_middle_vis" type="mesh" mesh="l_thumb_middle_vis" material="l_thumb_material" group="1" contype="0" conaffinity="0"/>
                                                      <geom name="l_thumb_middle_col" type="mesh" mesh="l_thumb_middle_col" mass="0.1" />
                                                      <site name="site_l_thumb_middle" size="0.01" material="site_left_hand"/>

                                                      <!-- Thumb Distal -->
                                                      <body name="l_thumb_distal" pos="0.020248 -0.010156 -0.0012" quat="1 0 0 0">
                                                          <joint name="joint_l_thumb_distal" type="hinge" pos="0 0 0" axis="0 0 -1" range="0 0.77" limited="true" damping="3"/>
                                                          <geom name="l_thumb_distal_vis" type="mesh" mesh="l_thumb_distal_vis" material="l_thumb_distal_material" group="1" contype="0" conaffinity="0"> </geom>
                                                          <geom name="l_thumb_distal_col" type="mesh" mesh="l_thumb_distal_col" mass="0.1" />
                                                          <site name="site_l_thumb_distal" size="0.01" material="site_left_hand"/>
                                                      </body>
                                                      <!-- End of Thumb Distal -->
                                                  </body>
                                                  <!-- End of Thumb Middle -->
                                              </body>
                                              <!-- End of Thumb Proximal 2 -->
                                          </body>
                                          <!-- End of Thumb Proximal 1 -->
                                      </body>
                                      <!-- End of Thumb -->

                                      <!-- Index finger -->
                                      <body name="l_index" pos="0 0 0">
                                          <!-- Index Proximal -->
                                          <body name="l_index_proximal" pos="0.0022853 -0.10493 0.032268" quat="0.99985 -0.01745 0.0 0.0">
                                              <joint name="joint_l_index_proximal" type="hinge" pos="0 0 0" axis="0 0 -1" range="0 1.62" limited="true" damping="3"/>
                                              <site name="site_l_index_proximal" size="0.01" material="site_left_hand"/>
                                              <geom name="l_index_proximal_vis" type="mesh" mesh="l_index_proximal_vis" material="l_index_material" group="1" contype="0" conaffinity="0"/>
                                              <geom name="l_index_proximal_col" type="mesh" mesh="l_index_proximal_col" mass="0.1" />
                                              <!-- Index Distal -->
                                              <body name="l_index_distal" pos="-0.0024229 -0.032041 -0.001" quat="1 0 0 0">
                                                  <joint name="joint_l_index_distal" type="hinge" pos="0 0 0" axis="0 0 -1" range="0 1.82" limited="true" damping="3"/>
                                                  <site name="site_l_index_distal" size="0.01" material="site_left_hand"/>
                                                  <geom name="l_index_distal_vis" type="mesh" mesh="l_index_distal_vis" material="l_index_material" group="1" contype="0" conaffinity="0"/>
                                                  <geom name="l_index_distal_col" type="mesh" mesh="l_index_distal_col" mass="0.1" />
                                              </body>
                                              <!-- End of Index Distal -->
                                          </body>
                                          <!-- End of Index Proximal -->
                                      </body>
                                      <!-- End of Index finger -->
                                      <!-- Middle finger -->
                                      <body name="l_middle" pos="0 0 0">
                                          <!-- Middle Proximal -->
                                          <body name="l_middle_proximal" pos="0.0022853 -0.1055 0.01295" quat="1 0 0 0">
                                              <joint name="joint_l_middle_proximal" type="hinge" pos="0 0 0" axis="0 0 -1" range="0 1.62" limited="true" damping="3"/>
                                              <site name="site_l_middle_proximal" size="0.01" material="site_left_hand"/>
                                              <geom name="l_middle_proximal_vis" type="mesh" mesh="l_middle_proximal_vis" material="l_middle_material" group="1" contype="0" conaffinity="0"/>
                                              <geom name="l_middle_proximal_col" type="mesh" mesh="l_middle_proximal_col" mass="0.1" />
                                              <!-- Middle Distal -->
                                              <body name="l_middle_distal" pos="-0.0024229 -0.032041 -0.001" quat="1 0 0 0">
                                                  <joint name="joint_l_middle_distal" type="hinge" pos="0 0 0" axis="0 0 -1" range="0 1.82" limited="true" damping="3"/>
                                                  <site name="site_l_middle_distal" size="0.01" material="site_left_hand"/>
                                                  <geom name="l_middle_distal_vis" type="mesh" mesh="l_middle_distal_vis" material="l_middle_material" group="1" contype="0" conaffinity="0"/>
                                                  <geom name="l_middle_distal_col" type="mesh" mesh="l_middle_distal_col" mass="0.1" />
                                              </body>
                                              <!-- End of Middle Distal -->
                                          </body>
                                          <!-- End of Middle Proximal -->
                                      </body>
                                      <!-- End of Middle finger -->

                                      <!-- Ring finger -->
                                      <body name="l_ring" pos="0 0 0">
                                          <!-- Ring Proximal -->
                                          <body name="l_ring_proximal" pos="0.0022853 -0.10531 -0.0062872" quat="0.99966 0.02618 0.0 0.0">
                                              <joint name="joint_l_ring_proximal" type="hinge" pos="0 0 0" axis="0 0 -1" range="0 1.62" limited="true" damping="3"/>
                                              <site name="site_l_ring_proximal" size="0.01" material="site_left_hand"/>
                                              <geom name="l_ring_proximal_vis" type="mesh" mesh="l_ring_proximal_vis" material="l_ring_material" group="1" contype="0" conaffinity="0"/>
                                              <geom name="l_ring_proximal_col" type="mesh" mesh="l_ring_proximal_col" mass="0.1" />
                                              <!-- Ring Distal -->
                                              <body name="l_ring_distal" pos="-0.0024229 -0.032041 -0.001" quat="1 0 0 0">
                                                  <joint name="joint_l_ring_distal" type="hinge" pos="0 0 0" axis="0 0 -1" range="0 1.75" limited="true" damping="3"/>
                                                  <site name="site_l_ring_distal" size="0.01" material="site_left_hand"/>
                                                  <geom name="l_ring_distal_vis" type="mesh" mesh="l_ring_distal_vis" material="l_ring_material" group="1" contype="0" conaffinity="0"/>
                                                  <geom name="l_ring_distal_col" type="mesh" mesh="l_ring_distal_col" mass="0.1" />
                                              </body>
                                              <!-- End of Ring Distal -->
                                          </body>
                                          <!-- End of Ring Proximal -->
                                      </body>
                                      <!-- End of Ring finger -->

                                      <!-- Pinky finger -->
                                      <body name="l_pinky" pos="0 0 0">
                                          <!-- Pinky Proximal -->
                                          <body name="l_pinky_proximal" pos="0.0022853 -0.10411 -0.025488" quat="0.99863 0.05234 0.0 0.0">
                                              <joint name="joint_l_pinky_proximal" type="hinge" pos="0 0 0" axis="0 0 -1" range="0 1.62" limited="true" damping="3"/>
                                              <site name="site_l_pinky_proximal" size="0.01" material="site_left_hand"/>
                                              <geom name="l_pinky_proximal_vis" type="mesh" mesh="l_pinky_proximal_vis" material="l_pinky_material" group="1" contype="0" conaffinity="0"/>
                                              <geom name="l_pinky_proximal_col" type="mesh" mesh="l_pinky_proximal_col" mass="0.1" />
                                              <!-- Pinky Distal -->
                                              <body name="l_pinky_distal" pos="-0.0024229 -0.032041 -0.001" quat="1 0 0 0">
                                                  <joint name="joint_l_pinky_distal" type="hinge" pos="0 0 0" axis="0 0 -1" range="0 1.87" limited="true" damping="3"/>
                                                  <site name="site_l_pinky_distal" size="0.01" material="site_left_hand"/>
                                                  <geom name="l_pinky_distal_vis" type="mesh" mesh="l_pinky_distal_vis" material="l_pinky_material" group="1" contype="0" conaffinity="0"/>
                                                  <geom name="l_pinky_distal_col" type="mesh" mesh="l_pinky_distal_col" mass="0.1" />
                                              </body>
                                              <!-- End of Pinky Distal -->
                                          </body>
                                          <!-- End of Pinky Proximal -->
                                      </body>
                                      <!-- End of Pinky finger -->

                                  </body>
                                  <!-- End of Palm -->
                              </body>
                              </body>
                              
                        </body>
                      </body>
                    </body>
                  </body>
                </body>
              </body>
            </body>
            <body name="right_shoulder_pitch_link" pos="0.0039563 -0.10021 0.24778"
              quat="0.990264 -0.139201 1.38722e-05 9.86868e-05">
              <inertial pos="0 -0.035892 -0.011628" quat="0.68225 -0.326267 0.0130458 0.654152" mass="0.718"
                diaginertia="0.000465864 0.000432842 0.000406394"/>
              <joint name="right_shoulder_pitch_joint" axis="0 1 0" range="-3.0892 2.6704" actuatorfrcrange="-25 25"/>
              <geom class="visual" mesh="right_shoulder_pitch_link"/>
              <geom size="0.03 0.025" pos="0 -0.04 -0.01" quat="0.707107 0 0.707107 0" type="cylinder" class="collision"/>
              <body name="right_shoulder_roll_link" pos="0 -0.038 -0.013831" quat="0.990268 0.139172 0 0">
                <inertial pos="-0.000227 -0.00727 -0.063243" quat="0.712604 -0.00710317 -0.0196223 0.701256"
                  mass="0.643" diaginertia="0.000691311 0.000618011 0.000388977"/>
                <joint name="right_shoulder_roll_joint" axis="1 0 0" range="-2.2515 1.5882" actuatorfrcrange="-25 25"/>
                <geom class="visual" mesh="right_shoulder_roll_link"/>
                <geom size="0.03 0.015" pos="-0.004 -0.006 -0.053" type="cylinder" class="collision"/>
                <body name="right_shoulder_yaw_link" pos="0 -0.00624 -0.1032">
                  <inertial pos="0.010773 0.002949 -0.072009" quat="0.687134 -0.0679942 -0.0964829 0.716879"
                    mass="0.734" diaginertia="0.00106187 0.00103217 0.000400661"/>
                  <joint name="right_shoulder_yaw_joint" axis="0 0 1" range="-2.618 2.618" actuatorfrcrange="-25 25"/>
                  <geom class="visual" mesh="right_shoulder_yaw_link"/>
                  <geom class="collision" mesh="right_shoulder_yaw_link"/>
                  <body name="right_elbow_link" pos="0.015783 0 -0.080518">
                    <inertial pos="0.064956 -0.004454 -0.010062" quat="0.388129 0.388821 0.636132 0.541765" mass="0.6"
                      diaginertia="0.000443035 0.000421612 0.000259353"/>
                    <joint name="right_elbow_joint" axis="0 1 0" range="-1.0472 2.0944" actuatorfrcrange="-25 25"/>
                    <geom class="visual" mesh="right_elbow_link"/>
                    <geom name="right_elbow_collision" class="collision" type="capsule" size="0.05" fromto="0 0 0 0.1 0 0" rgba=".2 .6 .2 .2" group="3"/>
                    <body name="right_wrist_roll_link" pos="0.1 -0.00188791 -0.01">
                      <inertial pos="0.0171394 -0.000537591 4.8864e-07" quat="0.411667 0.575338 -0.411094 0.574906"
                        mass="0.085445" diaginertia="5.48211e-05 4.96646e-05 3.57798e-05"/>
                      <joint name="right_wrist_roll_joint" axis="1 0 0" range="-1.97222 1.97222"
                        actuatorfrcrange="-25 25"/>
                      <geom class="visual" mesh="right_wrist_roll_link"/>
                      <geom class="collision" mesh="right_wrist_roll_link"/>
                      <body name="right_wrist_pitch_link" pos="0.038 0 0">
                        <inertial pos="0.0229999 0.00111685 -0.00111658" quat="0.643608 0.293036 0.661363 0.249998"
                          mass="0.48405" diaginertia="0.000430353 0.000429873 0.000164648"/>
                        <joint name="right_wrist_pitch_joint" axis="0 1 0" range="-1.61443 1.61443"
                          actuatorfrcrange="-5 5"/>
                        <geom class="visual" mesh="right_wrist_pitch_link"/>
                        <geom class="collision" mesh="right_wrist_pitch_link"/>
                        <body name="right_wrist_yaw_link" pos="0.046 0 0">
                          <inertial pos="0.0885506 -0.00212216 -0.000374562" quat="0.505358 0.513241 0.493844 0.487149"
                            mass="0.457415" diaginertia="0.00105989 0.000895419 0.000323842"/>
                          <joint name="right_wrist_yaw_joint" axis="0 0 1" range="-1.61443 1.61443"
                            actuatorfrcrange="-5 5"/>


                            <geom class="visual" mesh="right_wrist_yaw_link"/>
                          <geom class="collision" mesh="right_wrist_yaw_link"/>

                            

                            <site name="right_palm" pos="0.1 0 0"/>

                           <body name="right_hand" pos="0.03 0 0" euler="0 0 0" childclass="inspire">

                              <body name="right_hand_fake" pos="0 0 0"  euler="0 -3.14 -1.67">

                                <!-- <geom name="x_axis_r" type="box" pos="0.1 0 0" size="0.01 0.01 0.01" rgba="1 0 0 1" group="1" contype="0" conaffinity="0"/>
                                  <geom name="y_axis_r" type="box" pos="0 0.1 0" size="0.01 0.01 0.01" rgba="0 1 0 1" group="1" contype="0" conaffinity="0"/>
                                  <geom name="z_axis_r" type="box" pos="0 0 0.1" size="0.01 0.01 0.01" rgba="0 0 1 1" group="1" contype="0" conaffinity="0"/> -->
                          <!-- <body name="right_hand" pos="0.1 0 0" quat="0 0.707107 0 -0.707107"> -->
                              <site name="r_ft_frame" pos="0 0 0" size="0.01 0.01 0.01" rgba="1 0 0 0" type="sphere" group="1"/>
                              <inertial diaginertia="0 0 0" mass="0" pos="0 0 0"/>
                              <body name="r_eef" pos="0 0 0" quat="0.707 0. -0.707 0.">
                                  <site name="r_grip_site" pos="0 0 0" size="0.01 0.01 0.01" rgba="1 1 0 1" type="sphere" group="2"/>
                                  <site name="r_ee_x" pos="0.1 0 0" size="0.005 .1"  quat="0.707105  0 0.707108 0 " rgba="1 0 0 0" type="cylinder" group="1"/>
                                  <site name="r_ee_y" pos="0 0.1 0" size="0.005 .1" quat="0.707105 0.707108 0 0" rgba="0 1 0 0" type="cylinder" group="1"/>
                                  <site name="r_ee_z" pos="0 0 0.1" size="0.005 .1" quat="1 0 0 0" rgba="0 0 1 0" type="cylinder" group="1"/>
                                  <!-- This site was added for visualization. -->
                                  <!-- <site name="r_grip_site_cylinder" pos="0 0 0" quat="-0.5 -0.5 -0.5 0.5" size="0.005 0.5" rgba="0 1 0 0.3" type="cylinder" group="1"/> -->
                              </body>

                              <!-- Palm  -->
                              <body name="r_palm" pos="0 0 0">
                                  <!-- <inertial pos="-0.0014004 -0.052388 -0.0022404" quat="1 0 0 0" mass="0.10331">
                                      <inertia ixx="9.814E-05" ixy="3.1871E-06" ixz="-1.475E-06" iyy="6.4612E-05" iyz="2.4108E-06" izz="5.5131E-05"/>
                                  </inertial> -->
                                  <!-- Palm Visual -->
                                  <geom name="r_palm_vis" type="mesh" mesh="r_palm_vis" material="r_base_material" group="1" contype="0" conaffinity="0"/>
                                  <!-- Palm Collision -->
                                  <geom name="r_palm_col" type="mesh" mesh="r_palm_col" mass="0.1" />

                                  <!-- Thumb -->
                                  <body name="r_thumb" pos="0. 0. 0.">
                                      <!-- Thumb Proximal 1 -->
                                      <body name="r_thumb_proximal_1" pos="-0.01496 -0.0375 -0.02045" quat="0.5 0.5 -0.5 0.5">
                                          <joint name="joint_r_thumb_proximal_1" type="hinge" pos="0 0 0" axis="0 0 -1" range="0 1.30" limited="true" damping="3"/>
                                          <!-- <site name="site_thumb_proximal_1" size="0.01" material="site_right_hand"/> -->
                                          <geom name="r_thumb_proximal_vis" type="mesh" mesh="r_thumb_proximal_1_vis" material="r_thumb_material" group="1" contype="0" conaffinity="0"> </geom>
                                          <geom name="r_thumb_proximal_col" type="mesh" mesh="r_thumb_proximal_1_col" mass="0.1" />

                                          <!-- Thumb Proximal 2 -->
                                          <body name="r_thumb_proximal_2" pos="-0.0088099 0.010892 -0.00925" quat="0.1 0.1 0.7 0.7">
                                              <joint name="joint_r_thumb_proximal_2" type="hinge" pos="0 0 0" axis="0 0 1" range="0 0.68" limited="true" damping="3" />
                                              <geom name="r_thumb_proximal_2_vis" type="mesh" mesh="r_thumb_proximal_2_vis" material="r_thumb_material" group="1" contype="0" conaffinity="0"> </geom>
                                              <geom name="r_thumb_proximal_2_col" type="mesh" mesh="r_thumb_proximal_2_col" mass="0.1" />

                                              <site name="site_r_thumb_proximal_2" size="0.01" material="site_right_hand"/>

                                              <!-- Thumb Middle -->
                                              <body name="r_thumb_middle" pos="0.04407 0.034553 -0.0008" quat="1 0 0 0">
                                                  <joint name="joint_r_thumb_middle" type="hinge" pos="0 0 0" axis="0 0 1" range="0 0.68" limited="true" damping="3"/>
                                                  <geom name="r_thumb_middle_vis" type="mesh" mesh="r_thumb_middle_vis" material="r_thumb_material" group="1" contype="0" conaffinity="0"/>
                                                  <geom name="r_thumb_middle_col" type="mesh" mesh="r_thumb_middle_col" mass="0.1" />
                                                  <site name="site_r_thumb_middle" size="0.01" material="site_right_hand"/>

                                                  <!-- Thumb Distal -->
                                                  <body name="r_thumb_distal" pos="0.020248 0.010156 -0.0012" quat="1 0 0 0">
                                                      <joint name="joint_r_thumb_distal" type="hinge" pos="0 0 0" axis="0 0 1" range="0 0.77" limited="true" damping="3"/>
                                                      <geom name="r_thumb_distal_vis" type="mesh" mesh="r_thumb_distal_vis" material="r_thumb_distal_material" group="1" contype="0" conaffinity="0"> </geom>
                                                      <geom name="r_thumb_distal_col" type="mesh" mesh="r_thumb_distal_col" mass="0.1" />
                                                      <site name="site_r_thumb_distal" size="0.01" material="site_right_hand"/>
                                                  </body>
                                                  <!-- End of Thumb Distal -->
                                              </body>
                                              <!-- End of Thumb Middle -->
                                          </body>
                                          <!-- End of Thumb Proximal 2 -->
                                      </body>
                                      <!-- End of Thumb Proximal 1 -->
                                  </body>
                                  <!-- End of Thumb -->

                                  <!-- Index finger -->
                                  <body name="r_index" pos="0 0 0">
                                      <!-- Index Proximal -->
                                      <body name="r_index_proximal" pos="0.0022853 -0.10493 -0.032268" quat="0.01745 -0.99985 0.0 0.0">
                                          <joint name="joint_r_index_proximal" type="hinge" pos="0 0 0" axis="0 0 1" range="0 1.62" limited="true" damping="3"/>
                                          <site name="site_r_index_proximal" size="0.01" material="site_right_hand"/>
                                          <geom name="r_index_proximal_vis" type="mesh" mesh="r_index_proximal_vis" material="r_index_material" group="1" contype="0" conaffinity="0"/>
                                          <geom name="r_index_proximal_col" type="mesh" mesh="r_index_proximal_col" mass="0.1" />
                                          <!-- Index Distal -->
                                          <body name="r_index_distal" pos="-0.0026138 0.032026 -0.001" quat="1 0 0 0">
                                              <joint name="joint_r_index_distal" type="hinge" pos="0 0 0" axis="0 0 1" range="0 1.82" limited="true" damping="3"/>
                                              <site name="site_r_index_distal" size="0.01" material="site_right_hand"/>
                                              <geom name="r_index_distal_vis" type="mesh" mesh="r_index_distal_vis" material="r_index_material" group="1" contype="0" conaffinity="0"/>
                                              <geom name="r_index_distal_col" type="mesh" mesh="r_index_distal_col" mass="0.1" />
                                          </body>
                                          <!-- End of Index Distal -->
                                      </body>
                                      <!-- End of Index Proximal -->
                                  </body>
                                  <!-- End of Index finger -->
                                  <!-- Middle finger -->
                                  <body name="r_middle" pos="0 0 0">
                                      <!-- Middle Proximal -->
                                      <body name="r_middle_proximal" pos="0.0022853 -0.1055 -0.01295" quat="0 -1 0.0 0.0">
                                          <joint name="joint_r_middle_proximal" type="hinge" pos="0 0 0" axis="0 0 1" range="0 1.62" limited="true" damping="3"/>
                                          <site name="site_r_middle_proximal" size="0.01" material="site_right_hand"/>
                                          <geom name="r_middle_proximal_vis" type="mesh" mesh="r_middle_proximal_vis" material="r_middle_material" group="1" contype="0" conaffinity="0"/>
                                          <geom name="r_middle_proximal_col" type="mesh" mesh="r_middle_proximal_col" mass="0.1" />
                                          <!-- Middle Distal -->
                                          <body name="r_middle_distal" pos="-0.0024229 0.032041 -0.001" quat="1 0 0 0">
                                              <joint name="joint_r_middle_distal" type="hinge" pos="0 0 0" axis="0 0 1" range="0 1.82" limited="true" damping="3"/>
                                              <site name="site_r_middle_distal" size="0.01" material="site_right_hand"/>
                                              <geom name="r_middle_distal_vis" type="mesh" mesh="r_middle_distal_vis" material="r_middle_material" group="1" contype="0" conaffinity="0"/>
                                              <geom name="r_middle_distal_col" type="mesh" mesh="r_middle_distal_col" mass="0.1" />
                                          </body>
                                          <!-- End of Middle Distal -->
                                      </body>
                                      <!-- End of Middle Proximal -->
                                  </body>
                                  <!-- End of Middle finger -->

                                  <!-- Ring finger -->
                                  <body name="r_ring" pos="0 0 0">
                                      <!-- Ring Proximal -->
                                      <body name="r_ring_proximal" pos="0.0022853 -0.10531 0.0062872" quat="0.02619 0.99966 0.0 0.0">
                                          <joint name="joint_r_ring_proximal" type="hinge" pos="0 0 0" axis="0 0 1" range="0 1.62" limited="true" damping="3"/>
                                          <site name="site_r_ring_proximal" size="0.01" material="site_right_hand"/>
                                          <geom name="r_ring_proximal_vis" type="mesh" mesh="r_ring_proximal_vis" material="r_ring_material" group="1" contype="0" conaffinity="0"/>
                                          <geom name="r_ring_proximal_col" type="mesh" mesh="r_ring_proximal_col" mass="0.1" />
                                          <!-- Ring Distal -->
                                          <body name="r_ring_distal" pos="-0.0024229 0.032041 -0.001" quat="1 0 0 0">
                                              <joint name="joint_r_ring_distal" type="hinge" pos="0 0 0" axis="0 0 1" range="0 1.75" limited="true" damping="3"/>
                                              <site name="site_r_ring_distal" size="0.01" material="site_right_hand"/>
                                              <geom name="r_ring_distal_vis" type="mesh" mesh="r_ring_distal_vis" material="r_ring_material" group="1" contype="0" conaffinity="0"/>
                                              <geom name="r_ring_distal_col" type="mesh" mesh="r_ring_distal_col" mass="0.1" />
                                          </body>
                                          <!-- End of Ring Distal -->
                                      </body>
                                      <!-- End of Ring Proximal -->
                                  </body>
                                  <!-- End of Ring finger -->

                                  <!-- Pinky finger -->
                                  <body name="r_pinky" pos="0 0 0">
                                      <!-- Pinky Proximal -->
                                      <body name="r_pinky_proximal" pos="0.0022853 -0.10411 0.025488" quat="0.05232 0.99863 0.0 0.0">
                                          <joint name="joint_r_pinky_proximal" type="hinge" pos="0 0 0" axis="0 0 1" range="0 1.62" limited="true" damping="3"/>
                                          <site name="site_r_pinky_proximal" size="0.01" material="site_right_hand"/>
                                          <geom name="r_pinky_proximal_vis" type="mesh" mesh="r_pinky_proximal_vis" material="r_pinky_material" group="1" contype="0" conaffinity="0"/>
                                          <geom name="r_pinky_proximal_col" type="mesh" mesh="r_pinky_proximal_col" mass="0.1" />
                                          <!-- Pinky Distal -->
                                          <body name="r_pinky_distal" pos="-0.0024229 0.032041 -0.001" quat="1 0 0 0">
                                              <joint name="joint_r_pinky_distal" type="hinge" pos="0 0 0" axis="0 0 1" range="0 1.87" limited="true" damping="3"/>
                                              <site name="site_r_pinky_distal" size="0.01" material="site_right_hand"/>
                                              <geom name="r_pinky_distal_vis" type="mesh" mesh="r_pinky_distal_vis" material="r_pinky_material" group="1" contype="0" conaffinity="0"/>
                                              <geom name="r_pinky_distal_col" type="mesh" mesh="r_pinky_distal_col" mass="0.1" />
                                          </body>
                                          <!-- End of Pinky Distal -->
                                      </body>
                                      <!-- End of Pinky Proximal -->
                                  </body>
                                  <!-- End of Pinky finger -->

                              </body>
                              <!-- End of Palm -->
                          </body>
                          </body>


                        </body>
                      </body>
                    </body>
                  </body>
                </body>
              </body>
            </body>
          </body>
        </body>
      </body>
    </body>
  </worldbody>

  <actuator>
    <position class="g1" name="left_hip_pitch_joint" joint="left_hip_pitch_joint"/>
    <position class="g1" name="left_hip_roll_joint" joint="left_hip_roll_joint"/>
    <position class="g1" name="left_hip_yaw_joint" joint="left_hip_yaw_joint"/>
    <position class="g1" name="left_knee_joint" joint="left_knee_joint"/>
    <position class="g1" name="left_ankle_pitch_joint" joint="left_ankle_pitch_joint"/>
    <position class="g1" name="left_ankle_roll_joint" joint="left_ankle_roll_joint"/>
    <position class="g1" name="right_hip_pitch_joint" joint="right_hip_pitch_joint"/>
    <position class="g1" name="right_hip_roll_joint" joint="right_hip_roll_joint"/>
    <position class="g1" name="right_hip_yaw_joint" joint="right_hip_yaw_joint"/>
    <position class="g1" name="right_knee_joint" joint="right_knee_joint"/>
    <position class="g1" name="right_ankle_pitch_joint" joint="right_ankle_pitch_joint"/>
    <position class="g1" name="right_ankle_roll_joint" joint="right_ankle_roll_joint"/>

    <position class="g1" name="waist_yaw_joint" joint="waist_yaw_joint"/>
    <position class="g1" name="waist_roll_joint" joint="waist_roll_joint"/>
    <position class="g1" name="waist_pitch_joint" joint="waist_pitch_joint"/>

    <position class="g1" name="left_shoulder_pitch_joint" joint="left_shoulder_pitch_joint"/>
    <position class="g1" name="left_shoulder_roll_joint" joint="left_shoulder_roll_joint"/>
    <position class="g1" name="left_shoulder_yaw_joint" joint="left_shoulder_yaw_joint"/>
    <position class="g1" name="left_elbow_joint" joint="left_elbow_joint"/>
    <position class="g1" name="left_wrist_roll_joint" joint="left_wrist_roll_joint"/>
    <position class="g1" name="left_wrist_pitch_joint" joint="left_wrist_pitch_joint"/>
    <position class="g1" name="left_wrist_yaw_joint" joint="left_wrist_yaw_joint"/>

    <position class="g1" name="right_shoulder_pitch_joint" joint="right_shoulder_pitch_joint"/>
    <position class="g1" name="right_shoulder_roll_joint" joint="right_shoulder_roll_joint"/>
    <position class="g1" name="right_shoulder_yaw_joint" joint="right_shoulder_yaw_joint"/>
    <position class="g1" name="right_elbow_joint" joint="right_elbow_joint"/>
    <position class="g1" name="right_wrist_roll_joint" joint="right_wrist_roll_joint"/>
    <position class="g1" name="right_wrist_pitch_joint" joint="right_wrist_pitch_joint"/>
    <position class="g1" name="right_wrist_yaw_joint" joint="right_wrist_yaw_joint"/>

    <position joint="joint_r_thumb_proximal_1" name="thumb_r_proximal_1_drive" ctrlrange="0 1.3"  kp="100" forcelimited="true" forcerange="-20 20"/>
    <position joint="joint_r_thumb_proximal_2" name="thumb_r_proximal_2_drive" ctrlrange="0 0.68" kp="100" forcelimited="true" forcerange="-20 20"/>
    <position joint="joint_r_index_proximal" name="index_r_proximal_drive" ctrlrange="0 1.62"  kp="100" forcelimited="true" forcerange="-20 20"/>
    <position joint="joint_r_middle_proximal" name="middle_r_proximal_drive" ctrlrange="0 1.62" kp="100" forcelimited="true" forcerange="-20 20"/>
    <position joint="joint_r_ring_proximal" name="ring_r_proximal_drive" ctrlrange="0 1.62" kp="100" forcelimited="true" forcerange="-20 20"/>
    <position joint="joint_r_pinky_proximal" name="pinky_r_proximal_drive" ctrlrange="0 1.62" kp="100" forcelimited="true" forcerange="-20 20"/>

    <position joint="joint_l_thumb_proximal_1" name="thumb_l_proximal_1_drive" ctrlrange="0 1.3" kp="100" forcelimited="true" forcerange="-20 20"/>
    <position joint="joint_l_thumb_proximal_2" name="thumb_l_proximal_2_drive" ctrlrange="0 0.68" kp="100" forcelimited="true" forcerange="-20 20"/>
    <position joint="joint_l_index_proximal" name="index_l_proximal_drive" ctrlrange="0 1.62" kp="100" forcelimited="true" forcerange="-20 20"/>
    <position joint="joint_l_middle_proximal" name="middle_l_proximal_drive" ctrlrange="0 1.62" kp="100" forcelimited="true" forcerange="-20 20"/>
    <position joint="joint_l_ring_proximal" name="ring_l_proximal_drive" ctrlrange="0 1.62" kp="100" forcelimited="true" forcerange="-20 20"/>
    <position joint="joint_l_pinky_proximal" name="pinky_l_proximal_drive" ctrlrange="0 1.62" kp="100" forcelimited="true" forcerange="-20 20"/>

  </actuator>

  <sensor>
    <gyro name="imu-torso-angular-velocity" site="imu_in_torso" noise="5e-4" cutoff="34.9"/>
    <accelerometer name="imu-torso-linear-acceleration" site="imu_in_torso" noise="1e-2" cutoff="157"/>
    <gyro name="imu-pelvis-angular-velocity" site="imu_in_pelvis" noise="5e-4" cutoff="34.9"/>
    <accelerometer name="imu-pelvis-linear-acceleration" site="imu_in_pelvis" noise="1e-2" cutoff="157"/>
  </sensor>
</mujoco>
